#(venv) C:\Users\User\Desktop\mysite\Networker>python manage.py runserver
Traceback (most recent call last):
  File "C:\Users\User\Desktop\mysite\Networker\manage.py", line 22, in <module>
    main()
  File "C:\Users\User\Desktop\mysite\Networker\manage.py", line 18, in main
    execute_from_command_line(sys.argv)
  File "C:\Users\User\Desktop\mysite\venv\lib\site-packages\django\core\management\__init__.py", line 419, in execute_from_command_line
    utility.execute()
  File "C:\Users\User\Desktop\mysite\venv\lib\site-packages\django\core\management\__init__.py", line 363, in execute
    settings.INSTALLED_APPS
  File "C:\Users\User\Desktop\mysite\venv\lib\site-packages\django\conf\__init__.py", line 82, in __getattr__
    self._setup(name)
  File "C:\Users\User\Desktop\mysite\venv\lib\site-packages\django\conf\__init__.py", line 69, in _setup
    self._wrapped = Settings(settings_module)
  File "C:\Users\User\Desktop\mysite\venv\lib\site-packages\django\conf\__init__.py", line 170, in __init__
    mod = importlib.import_module(self.SETTINGS_MODULE)
  File "C:\Program Files\WindowsApps\PythonSoftwareFoundation.Python.3.9_3.9.2032.0_x64__qbz5n2kfra8p0\lib\importlib\__init__.py", line 127, in import_module
    return _bootstrap._gcd_import(name[level:], package, level)
  File "<frozen importlib._bootstrap>", line 1030, in _gcd_import
  File "<frozen importlib._bootstrap>", line 1007, in _find_and_load
  File "<frozen importlib._bootstrap>", line 986, in _find_and_load_unlocked
  File "<frozen importlib._bootstrap>", line 680, in _load_unlocked
  File "<frozen importlib._bootstrap_external>", line 846, in exec_module
  File "<frozen importlib._bootstrap_external>", line 983, in get_code
  File "<frozen importlib._bootstrap_external>", line 913, in source_to_code
  File "<frozen importlib._bootstrap>", line 228, in _call_with_frames_removed
  File "C:\Users\User\Desktop\mysite\Networker\Networker\settings.py", line 1
    """
IndentationError: unexpected indent
# в папке setting.py нечаянно проставился пробел.
